<?xml version="1.0"?>  
<robot name="seeing_sim_car" xmlns:xacro="http://ros.org/wiki/xacro">  
  <property name="M_PI" value="3.14159"/>  
 
  <!-- Macro for SmartCar body. Including Gazebo extensions, but does not include Kinect -->  
  <include filename="$(find seeing_sim_car)/urdf/seeing_sim_car_gazebo.xacro"/>  
 
  <property name="base_x" value="0.33" />  
  <property name="base_y" value="0.33" />  
 
  <xacro:macro name="seeing_sim_car_body">  
 
 
  <link name="base_link">  
    <visual>  
      <geometry>  
        <cylinder length="0.08" radius="0.16"/>  
      </geometry>  
      <origin rpy="0 0 1.57057" xyz="0 0 0"/>  
      <material name="blue">  
      <color rgba="0 0 .8 1"/>  
      </material>  
   </visual>  
  </link>  

  <link name="front_fit_wheel">  
    <visual>  
      <geometry>  
        <cylinder length=".02" radius="0.025"/>  
      </geometry>  
      <material name="black">  
        <color rgba="0 0 0 1"/>  
      </material>  
    </visual>  
  </link>  

  <joint name="front_fit_wheel_joint" type="fixed">  
    <axis xyz="0 0 1"/>  
    <parent link="base_link"/>  
    <child link="front_fit_wheel"/>  
    <origin rpy="0 1.57075 0" xyz="0 0.12 -0.025"/>  
    <limit effort="100" velocity="100"/>  
    <joint_properties damping="0.0" friction="0.0"/>  
  </joint>  
 
 <link name="left_back_wheel">  
    <visual>  
      <geometry>  
        <cylinder length=".02" radius="0.025"/>  
      </geometry>  
      <material name="black">  
        <color rgba="0 0 0 1"/>  
      </material>  
   </visual>  
  </link>  
 
  <joint name="left_back_wheel_joint" type="continuous">  
    <axis xyz="0 0 1"/>  
    <parent link="base_link"/>  
    <child link="left_back_wheel"/>  
    <origin rpy="0 1.57075 0" xyz="-0.13 0 -0.025"/>  
    <limit effort="100" velocity="100"/>  
    <joint_properties damping="0.0" friction="0.0"/>  
  </joint>  
 
  <link name="right_back_wheel">  
    <visual>  
      <geometry>  
        <cylinder length=".02" radius="0.025"/>  
      </geometry>  
      <material name="black">  
        <color rgba="0 0 0 1"/>  
      </material>  
   </visual>  
  </link>  
 
 
  <joint name="right_back_wheel_joint" type="continuous">  
    <axis xyz="0 0 1"/>  
    <parent link="base_link"/>  
    <child link="right_back_wheel"/>  
    <origin rpy="0 1.57075 0" xyz="0.13 0 -0.025"/>  
    <limit effort="100" velocity="100"/>  
    <joint_properties damping="0.0" friction="0.0"/>  
  </joint>  
 
  <link name="base_laser_link">  
    <visual>  
      <geometry>  
        <cylinder length="0.08" radius="0.04"/>  
      </geometry>  
      <material name="white">  
        <color rgba="1 1 1 1"/>  
      </material>  
     </visual>  
  </link>  
 
  <joint name="laser" type="fixed">  
    <parent link="base_link"/>  
    <child link="base_laser_link"/>
    <origin rpy="0 0 0" xyz="0 -0.135 0.04"/>  
  </joint>  
  </xacro:macro>  
 
</robot>
